Workbook
Name _xlchart.v5.1: #REF!
Name _xlchart.v5.2: #REF!
Name _xlchart.v5.6: #REF!
Name _xlchart.v5.5: #REF!
Name _xlchart.v5.7: #REF!
Name _xlchart.v5.0: #REF!
Name _xlchart.v5.3: #REF!
Name _xlchart.v5.4: #REF!
Name _xlchart.v5.9: #REF!
Name _xlchart.v5.8: #REF!

Sheet SWAP_Connections
A1: state | B1: name | C1: agency | D1: type | E1: notes
A2: Alabama | B2: Paul Johnson | C2: Alabama Department of Conservation and Natural Resources ADCNR | D2: state
A3: Alabama | B3: Kevin Anson | C3: Alabama Department of Conservation and Natural Resources ADCNR | D3: state
A4: Alabama | B4: Eric Soehren | C4: Alabama Department of Conservation and Natural Resources ADCNR | D4: state
A5: Alabama | B5: Jo Lewis | C5: Alabama Department of Conservation and Natural Resources ADCNR | D5: state
A6: Alabama | B6: Courtney Norman | C6: Alabama Department of Conservation and Natural Resources ADCNR | D6: state
A7: Alabama | B7: Ashley Peters | C7: Alabama Department of Conservation and Natural Resources ADCNR | D7: state
A8: Alabama | B8: Forrest Bailey | C8: Alabama Department of Conservation and Natural Resources ADCNR | D8: state
A9: Alabama | B9: Chuck Sykes | C9: Alabama Department of Conservation and Natural Resources ADCNR | D9: state
A10: Alabama | B10: Jim Schrenkel | C10: Alabama Department of Conservation and Natural Resources ADCNR | D10: state
A11: Alabama | B11: Casey Norris | C11: Alabama Department of Conservation and Natural Resources ADCNR | D11: state
A12: Alabama | B12: Nick Nichols | C12: Alabama Department of Conservation and Natural Resources ADCNR | D12: state
A13: Alabama | B13: Stan Cook | C13: Alabama Department of Conservation and Natural Resources ADCNR | D13: state
... A207: Alaska | B207: Kathy Lepley | C207: Galaxy Graphics | D207: business
A208: Alaska | C208: Alaska Natural Heritage Program UAA | D208: school
A209: Alaska | C209: Audubon Alaska | D209: ngo-nongame
A210: Alaska | C210: Juneau Audubon | D210: ngo-nongame
A211: Alaska | C211: US Fish and Wildlife Service USFWS | D211: federal
A212: Alaska | C212: Pacific Coast Joint Venture | D212: partnership
A213: Alaska | C213: US Geological Survey USGS | D213: federal
A214: Alaska | C214: National Park Service | D214: federal
A215: Alaska | C215: Alaska Fish Habitat Partnerships | D215: partnership
A216: Alaska | C216: American Fisheries Society Alaska Chapter | D216: ngo-consumptive
A217: Alaska | C217: University of Alaska Fairbanks | D217: school
A218: Alaska | C218: Boreal Partners in Flight | D218: partnership
A219: Alaska | C219: Alaska Raptor Group | D219: partnership
... A222: Alaska | C222: Association of Fish and Wildlife Agencies | D222: ngo-consumptive
A223: Arizona | B223: Joyce Francis | C223: Arizona Game and Fish Department AZGFD | D223: state
A224: Arizona | B224: Charles Hofer | C224: Arizona Game and Fish Department AZGFD | D224: state
A225: Arizona | B225: Matthew King | C225: Arizona Game and Fish Department AZGFD | D225: state
A226: Arizona | B226: Tiffany Finke | C226: Arizona Game and Fish Department AZGFD | D226: state
A227: Arizona | B227: Josh Avey | C227: Arizona Game and Fish Department AZGFD | D227: state
A228: Arizona | B228: Michael Barbour | C228: Arizona Game and Fish Department AZGFD | D228: state
A229: Arizona | B229: Zach Beard | C229: Arizona Game and Fish Department AZGFD | D229: state
A230: Arizona | B230: Erin Butler | C230: Arizona Game and Fish Department AZGFD | D230: state
A231: Arizona | B231: Chris Cantrell | C231: Arizona Game and Fish Department AZGFD | D231: state
A232: Arizona | B232: Julie Carter | C232: Arizona Game and Fish Department AZGFD | D232: state
A233: Arizona | B233: Barbara Cook | C233: Arizona Game and Fish Department AZGFD | D233: state
A234: Arizona | B234: Jom Cooley | C234: Arizona Game and Fish Department AZGFD | D234: state
... A300: Arizona | B300: Tim Howard | C300: Research Foundation for The State University of New York Environmental Science and Forestry SUNY | D300: school
...

Sheet All Agencies by State
A1: Alabama | B1: Alaska | C1: Arizona | D1: Arkansas | E1: California | F1: Colorado | G1: Connecticut | H1: Delaware | I1: Florida | J1: Georgia | K1: Hawaii | L1: Idaho | M1: Illinois | N1: Indiana | O1: Iowa | P1: Kansas | Q1: Kentucky | R1: Louisiana | S1: Maine | T1: Maryland | U1: Massachusetts | V1: Michigan | W1: Minnesota | X1: Mississippi | Y1: Missouri | Z1: Montana | AA1: Nebraska | AB1: Nevada | AC1: New Hampshire | AD1: New Jersey | AE1: New Mexico | AF1: North Carolina | AG1: North Dakota | AH1: Oklahoma | AI1: Oregon | AJ1: Pennsylvania | AK1: Rhode Island | AL1: South Carolina | AM1: South Dakota | AN1: Tennessee | AO1: Texas | AP1: Utah | AQ1: Vermont | AR1: Virginia | AS1: Washington | AT1: West Virginia | AU1: Wisconsin | AV1: Wyoming
A2: Alabama Clean Water Partnership | B2: Action Plan Coordinators from Idaho and Washington | C2: Altar Valley Conservation Alliance | D2: Arkansas Department of Environmental Quality | E2: Ascent Environmental, Inc | F2: Adams County Parks Department | G2: Appalachian Trail Conservancy | H2: Alexander Environmental Consulting | I2: American Museum of Natural History | J2: Abraham Baldwin Agricultural College | K2: Bishop Museum | L2: Boise State University, Intermountain Bird Observatory | M2: Association of Illinois Soil and Water Conservation Districts | N2: Ducks Unlimited | O2: American Fisheries Society | P2: Audubon Society | Q2: Asbury University | R2: Acadiana Park Nature Station | S2: Acadia National Park | T2: American Bird Conservancy | U2: Cape Cod Cranberry Growers Association | V2: Adrian College | W2: Audubon Minnesota | X2: 25x25 Alliance | Y2: American Bird Conservancy | Z2: American Wildlands | AA2: Audubon Society of Omaha | AB2: Arizona Game and Fish Department AZGFD | AC2: Antioch University New England | AD2: Atlantic City Electric | AE2: Arizona Game and Fish Department AZGFD | AF2: Appalachian State University | AG2: North Dakota Game and Fish Department | AH2: Cameron University | AI2: American Bird Conservancy | AJ2: American Fisheries Society | AK2: American Fisheries Society | AL2: Agriculture Canada | AM2: Badlands National Park | AN2: Arnold Air Force Base | AO2: Texas Parks and Wildlife Department | AP2: Bureau of Land Management | AQ2: Audubon Vermont | AR2: Accomack/Northampton Planning District Commission | AS2: Audubon Washington | AT2: Alabama Department of Conservation and Natural Resources ADCNR | AU2: All Things Wild Consulting | AV2: Association of Conservation Districts
A3: Alabama Cooperative Wildlife Unit | B3: Alaska Department of Fish and Game | C3: Arizona Game and Fish Department AZGFD | D3: Arkansas Game and Fish Commission | E3: Blue Earth Consultants | F3: Adams State College | G3: Aquarion Water Company | H3: Delaware Department of Agriculture | I3: Florida Department of Agriculture and Consumer Services | J3: Alabama Aquatic Biodiversity Center | K3: Hawaii Department of Land and Natural Resources | L3: College of Idaho | M3: Bird Conservation Network | N3: Duke Energy | O3: Buena Vista University | P3: Central Plains Society of Mammalogists | Q3: Austin Peay State University | R3: Audubon Institute | S3: Appalacian Conservation Biology | T3: Ann Arundel County Department of Recreation and Parks | U3: Charles River Watershed Association | V3: Alma College | W3: Consultant | X3: Audubon Mississippi | Y3: American Fisheries Society | Z3: Bureau of Land Management | AA3: Audubon Spring Creek Prairie | AB3: Bureau of Land Management | AC3: Appalachian Mountain Club | AD3: Buttonbush Design and Delineation | AE3: Arizona State University | AF3: Auburn University | AH3: Central Hardwoods Joint Venture | AI3: Association of Northwest Steelheaders | AJ3: American Rivers | AK3: American Heritage Rivers | AL3: Alderman Environmental Services | AM3: Black Hills State University | AN3: Austin Peay State University | AO3: University of Texas | AP3: Hawkwatch International | AQ3: Birds of Vermont Museum | AR3: Appalachian Landscape Conservation Cooperative | AS3: Black Hills Audubon | AT3: American University | AU3: Audubon Society | AV3: Audubon Wyoming
A4: Alabama Department of Conservation and Natural Resources ADCNR | B4: Alaska Fish Habitat Partnerships | C4: Arizona State University | D4: Arkansas Highway and Transportation Department | E4: Bureau of Land Management | F4: Audubon Society of Greater Denver | G4: Atlantic Coast Joint Venture | H4: Delaware Department of Natural Resources and Environmental Control | I4: Florida Department of Environmental Protection | J4: Appalachian State University | K4: Hawaii Institute of Marine Biology | L4: Defenders of Wildlife | M4: Boone County Conservation District | N4: Eppley Institute for Parks and Lands | O4: Butterfliz of Iowa | P4: Ducks Unlimited | Q4: Berea College | R4: Barataria-Terrebonne National Estuary | S4: Aroostook Band of MicMac Indians | T4: Audubon Maryland | U4: Conservation Law Foundation | V4: Central Michigan University | W4: Minnesota Department of Natural Resources | X4: Bureau of Land Management | Y4: American Tree Farm System | Z4: Center for Large Landscape Conservation | AA4: Breeding Bird Atlas | AB4: Great Basin Bird Observatory | AC4: Blue Ocean Society | AD4: Cape May National Wildlife Refuge | AE4: Audubon New Mexico | AF4: Audubon North Carolina | AH4: Cherokee Nation | AI4: Association of Oregon Counties | AJ4: American University | AK4: Applied Bio-Systems | AL4: Alligator Adventure | AM4: Bureau of Indian Affairs | AN4: Belmont University | AP4: Hill Air Force Base | AQ4: Consultant | AR4: Appalachian Mountain Joint Venture | AS4: Cascadia Partner Forum | AT4: Appalachian Mountain Joint Venture | AU4: Bad River Band | AV4: BP America
A5: Alabama Department of Environmental Management | B5: Alaska Natural Heritage Program UAA | C5: ASARCO | D5: Arkansas Natural Heritage Commission | E5: California Department of Fish and Wildlife | F5: Audubon Colorado | G5: Atlantic States Marine Fisheries Commission | H5: Delaware Museum of Natural History | I5: Florida Fish and Wildlife Conservation Commission | J5: Atlanta Audubon Society | K5: Hawaii Invasive Species Council | L5: Foundations of Success | M5: Byron Forest Preserve District | N5: Indiana Department of Environmental Management | O5: Consultant | P5: Environmental Division Fort Riley | Q5: Big South Fork National River and Recreation Area | R5: Bird Study Group | S5: Atlantic Salmon Federation | T5: Bowie State University | U5: Environmental League of Massachusetts | V5: Clinton River Watershed Council | W5: Minnesota Dragonfly Society | X5: Delta Wildlife | Y5: Animal and Plant Health Inspection Service | Z5: Defenders of Wildlife | AA5: Central College Iowa | AB5: Kearns and West | AC5: Connecticut Department of Energy and Environmental Protection | AD5: Conserve Wildlife Foundation of New Jersey | AE5: Bat Conservation International | AF5: Belize Foundation for Research and Environmental Education | AH5: East Central Oklahoma University | AI5: Audubon Society of Portland | AJ5: Atlas of Pennsylvania Butterflies | AK5: Atlantic Coast Fish Habitat Partnership Committee | AL5: Auburn University | AM5: Bureau of Land Management | AN5: Clinch-Powell Resource Conservation and Development Council | AP5: National Park Service | AQ5: Cougar Rewilding Foundation, Northeast Wolf Coalition | AR5: Chesapeake Bay Conservancy | AS5: EcoAdapt | AT5: Brooks Bird Club | AU5: Beaver Creek Nature Center | AV5: British Petroleum
A6: Alabama Department of Transportation | B6: Alaska Raptor Group | C6: Association of Environmental Professionals | D6: Arkansas State University | E6: California Department of Forestry and Fire Protection | F6: Back Country Hunters | G6: Audubon Connecticut | H6: Delaware Nature Society | I6: Florida Forest Service | J6: Atlanta Botanical Garden | K6: Hawaii Watershed Partnerships | L6: Gonzales-Stoller Surveillance, LLC | M6: Carroll County Soil and Water Conservation District | N6: Indiana Department of Natural Resources | O6: Drake University | P6: Fort Hays State University | Q6: Bluegrass Woodland | R6: Centenary Colllege of Louisiana | S6: Baxter State Park | T6: Calvert County Natural Resources Division | U6: Massachusetts Audubon | V6: Detroit Zoo | W6: Minnesota Odonata Survey Project | X6: Ducks Unlimited | Y6: Audubon Society of Missouri | Z6: Intermountain Joint Venture | AA6: Central Platte Natural Resources District | AB6: NatureServe | AC6: Consultant | AD6: D&R Greenway Land Trust | AE6: Big Picture Conservation | AF6: Catawba Land Conservancy | AH6: Emporia State University | AI6: Bureau of Indian Affairs | AJ6: Audubon Pennsylvania | AK6: Atlantic States-Rural Waters Association, Rose Island Lighthouse Foundation | AL6: Avian Research and conservation Institute | AM6: Bureau of Reclamation | AN6: Conservation Fisheries Inc | AP6: Natural Resources Conservation Service NRCS | AQ6: First Vermont Bird Atlas | AR6: Crater Planning District Commission | AS6: North Pacific Landscape Conservation Cooperative | AT6: Canaan Valley Institute | AU6: Carroll University | AV6: Bureau of Land Management
A7: Alabama Forestry Commission | B7: Alaska Shorebird Group | C7: Audubon Arizona | D7: Arkansas Tech University | E7: California Invasive Plant Council | F7: Betty Ford Alpine Gardens | G7: Beardsley Zoological Gardens | H7: Delaware State University | I7: Florida Forestry Association | J7: Auburn University | K7: HT Harvey and Associates | L7: Great Basin Landscape Conservation Cooperative | M7: Champaign County Forest Preserve District | N7: Indiana Department of Transportation | O7: Ducks Unlimited | P7: Friends of Kaw, Kansas Riverkeeper | Q7: Clarks River National Wildlife Refuge | R7: Center of Excellence COE | S7: Biodiversity Research Institute | T7: Coastal Resources Inc | U7: Massachusetts Division of Fisheries and Wildlife | V7: Ducks Unlimited | W7: Minnesota Ornithologists Union | X7: Grand Bay National Estuarine Research Reserve | Y7: Central Hardwoods Joint Venture | Z7: Montana Audubon | AA7: Chadron State College | AB7: Nevada Department of Wildlife | AC7: CrossCurrent Communications | AD7: Edwin B Forsythe National Wildlife Refuge | AE7: Black Hills State University | AF7: Clean Water Management Trust Fund | AH7: Fort Sill Military Reservation | AI7: City of Salem | AJ7: Audubon Society of Western Pennsylvania | AK7: Audubon Society | AL7: Cape Romain Bird Observatory | AM7: Cheyenne River Sioux Tribe | AN7: Cumberland Region Tomorrow | AP7: Round River Conservation Studies | AQ7: Green Mountain College | AR7: Eastern Brook Trout Joint Venture | AS7: Northwest Climate Science Center | AT7: Carnegie Museum of Natural History | AU7: Chadron State University | AV7: Carbon County Weed and Pest Medicine Bow Conservation District
A8: Alabama Geological Survey | B8: American Fisheries Society Alaska Chapter | C8: Audubon Southwest | D8: Audubon Arkansas | E8: California Native Plant Society | F8: BIO-Logic, Inc | G8: Connecticut Agricultural Experiment Station | H8: Lenape Tribe | I8: Florida Natural Areas Inventory | J8: Augusta Chronicle | K8: National Park Service | L8: Greater Yellowstone Coalition | M8: Chicago Academy of Sciences | N8: Indiana Farm Bureau | O8: E Resources Group | P8: Grassland Heritage Foundation | Q8: Copperhead Consulting | R8: Gulf Coast Joint Venture | S8: Brunswick-Topsham Land Trust | T8: Cornell University, eBird | U8: Massachusetts Rivers Alliance | V8: Eastern Michigan University | W8: Minnesota Zoo | X8: Gulf Coast Joint Venture | Y8: Conservation Federation of Missouri | Z8: Montana Fish, Wildlife and Parks | AA8: Concordia University | AB8: Nevada Division of Forestry | AC8: Ecosystem Management Consultants | AD8: ENSAC Endangered and Nongame Species Advisory Committee | AE8: Consultant | AF8: Clemson University | AH8: Gulf Coastal Prairies Landscape Conservation Cooperative | AI8: Clackamas Soil and Water Conservation District | AJ8: Bucknell University | AK8: Audubon Society of Rhode Island | AL8: Central Florida University | AM8: Crow Creek Sioux Tribe | AN8: Cumberland University | AP8: The Nature Conservancy | AQ8: Lake Champlain Basin Program | AR8: George Washington National Forest | AS8: Pacific Coast Joint Venture | AT8: Coalition of West Virginia Land Trusts | AU8: Chicago Field Museum | AV8: City of Cheyenne
A9: Alabama Power Company | B9: Association of Fish and Wildlife Agencies | C9: Be Outdoors Arizona | D9: Beaver Water District | E9: Catalina Conservancy | F9: Black Canyon Regional Land Trust | G9: Connecticut Animal Control Division | H9: Sarver Ecological | I9: Florida Power and Light Company | J9: Avian Research and conservation Institute | K9: Pacific Islands Climate Change Cooperative | L9: Idaho Cattle Association | M9: Chicago Wilderness | N9: Indiana Forest and Woodland Owners Association | O9: EarthTech | P9: Kansas Alliance for Wetlands and Streams | Q9: Cumberlands University | R9: Kentucky Department of Fish and Wildlife Resources | S9: Casco Bay Estuary Partnership | T9: Delmarva Low Impact Tourism Experiences | U9: Massachusetts Water Resources Authority | V9: Fisheries and Oceans Canada | W9: Ornithologist | X9: Gulf Coastal Plains and Ozarks Landscape Conservation Cooperative | Y9: Ducks Unlimited | Z9: Montana Natural Heritage Program | AA9: Congressmen Tom Osborne Office | AB9: Nevada Division of Natural Heritage | AC9: Great Bay National Estuarine Research Reserve | AD9: Great Egg Harbor Watershed Association | AE9: Furman University | AF9: Conservation Trust for North Carolina | AH9: Natural Resources Conservation Service NRCS | AI9: Coalition of Oregon Land Trusts | AJ9: Butterflies and Moths of North America | AK9: Block Island Bird Banding Station | AL9: Charleston Turtle and Tortoise Society | AM9: Ecosystem Management Research Institute | AN9: East Tennessee State University | AP9: US Army Dugway Proving Ground | AQ9: National Wildlife Federation | AR9: George Washington Planning District Commission | AS9: US Fish and Wildlife Service USFWS | AT9: Columbus Zoo | AU9: Consultant | AV9: Consultant
A10: Alabama Water Watch Auburn University | B10: Audubon Alaska | C10: Big Sandy NRCD | D10: Consultant | E10: Center for Collaborative Policy - California State University, Sacramento | F10: Boulder County | G10: Connecticut Audubon | H10: Terwilliger Consulting | I10: Florida Southern College | J10: A-Z Animals | K10: The Nature Conservancy | L10: Idaho Department of Fish and Game | M10: Clifftop Alliance | N10: Indiana Land Protection Allinace | O10: Harrison County Conservation Board | P10: Kansas Applied Remote Sensing Program | Q10: Daniel Boone National Forest | R10: Louisiana Asset Management Pool | S10: Coastal Mountains Land Trust | T10: Environmental Regulations Consultant Inc | U10: Massachusetts Water Works Association | V10: Friends of the Rouge | W10: Science Museum of Minnesota | X10: Gulf Restoration Network | Y10: Forest and Woodland Association of Missouri | Z10: National Park Service | AA10: DeSoto National Wildlife Refuge | AB10: New York Natural Heritage Program | AC10: High Branch Conservation Services | AD10: Great Swamp National Wildlife Refuge | AE10: National Park Service | AF10: Davidson College | AH10: Northeastern Oklahoma State University | AI10: Confederated Tribes of Coos, Lower Umpqua, and Suislaw Indians | AJ10: California University of Pennsylvania | AK10: Brook Trout Forever | AL10: Clemson University | AM10: Flandreau Santee Sioux Tribe | AN10: Fort Campbell Military Installation | AP10: US Fish and Wildlife Service USFWS | AQ10: North Branch Nature Center | AR10: Hampton Roads Planning District Commission | AS10: US Forest Service USFS | AT10: George Washington National Forest | AU10: Driftless Land Stewards | AV10: Defenders of Wildlife
A11: Alabama Wildlife Federation | B11: Boreal Partners in Flight | C11: Borderlands Restoration Network | D11: Henderson State University | E11: Central Valley Joint Venture | F11: Boulder County Audubon | G11: Connecticut College | H11: University of Delaware | I11: Florida Wildlife Legacy Initiative | J11: Captain Planet Foundation | K11: University of Hawaii | L11: Idaho Department of Lands | M11: Conservation Technologies | N11: Indiana State Department of Agriculture | O11: Hawkeye Flyfishing Association | P11: Kansas Biological Survey | Q11: Eastern Kentucky University | R11: Louisiana Department of Enviromental Quality | S11: Conservation Law Foundation | T11: FrogWatch USA | U11: The Nature Conservancy | V11: Golden-winged Warbler Conservation Initiative | W11: The Nature Conservancy | X11: Land Trust Alliance | Y11: Gulf Coastal Plains and Ozarks Landscape Conservation Cooperative | Z11: National Wildlife Federation | AA11: Ducks Unlimited | AB11: Pyramid Lake Paiute Tribe | AC11: Loon Preservation Committee | AD11: Monmouth Conservation Foundation | AE11: Natural Heritage New Mexico | AF11: Duke (Progress) Energy | AH11: Oaks and Prairies Joint Venture | AI11: Confederated Tribes of Siletz Indians of Oregon | AJ11: Carnegie Museum of Natural History | AK11: Brown University | AL11: Coastal Carolina University | AM11: Jewel Cave National Park | AN11: Freed Hardeman University | AP11: US Forest Service USFS | AQ11: Northwoods Stewardship Center | AR11: Middle Peninsula Planning District Commission | AS11: Washington Department of Fish and Wildlife | AT11: Marshall University | AU11: Ducks Unlimited | AV11: Encana
A12: Auburn University | B12: Galaxy Graphics | C12: Bureau of Land Management | D12: Lower Mississippi Valley Joint Venture | E12: Conservation Biology Institute | F12: Boulder County Nature Association | G12: Connecticut Conservation Advisory Council | H12: US Fish and Wildlife Service USFWS | I12: University of Florida | J12: CCR Environmental Consulting | K12: US Fish and Wildlife Service USFWS | L12: Idaho Governor's Office of Species Conservaiton | M12: Ducks Unlimited | N12: Indiana Wildlife Federation | O12: Ida County Conservation Board | P12: Kansas Cooperative Fish and Wildlife Research Unit | Q12: Fort Knox | R12: Louisiana Department of Wildlife and Fisheries | S12: Cornell University | T12: Frostburg State University | U12: Unnamed environmental law expert | V12: Grand Traverse Band of Ottawa and Chippewa Indians | W12: The Wildlife Society | X12: Land Trust for the Mississippi Coastal Plain | Y12: L-A-D Foundation | Z12: Natural Resources Conservation Service NRCS | AA12: Educator | AB12: The Nature Conservancy | AC12: Maine Department of Inland Fisheries and Wildlife | AD12: Monmouth County Audubon Society | AE12: New Mexico Audubon | AF12: Freshwater Mollusk Conservation Society | AH12: Oklahoma Conservation Commission | AI12: Confederated Tribes of the Grand Ronde | AJ12: Chesapeake Bay Foundation | AK12: Caputo and Wick LTD | AL12: Coastal Georgia Community College | AM12: Lower Brule Sioux Tribe | AN12: Gulf Coastal Plains and Ozarks Landscape Conservation Cooperative | AP12: Utah Department of Natural Resources | AQ12: Norwich University | AR12: National Park Service | AS12: Washington Department of Natural Resources | AT12: Monongahela National Forest | AU12: Forest County Potawatomi | AV12: E-Quant Consulting
A13: Birmingham-Southern College | B13: Juneau Audubon | C13: City of Flagstaff | D13: Mitigation Surveying Services, LLC | E13: Defenders of Wildlife | F13: Boulder County Parks & Open Space | G13: Connecticut Department of Agriculture | H13: US Geological Survey USGS | I13: US Fish and Wildlife Service USFWS | J13: Chattahoochee/Oconee National Forest | K13: US Geological Survey USGS | L13: Idaho State Department of Agriculture | M13: Forest Preserve District of Cook County | N13: Natural Resources Conservation Service NRCS | O13: Iowa Audubon | P13: Kansas Department of Health and Environment | Q13: Illinois Natural History Survey | R13: Louisiana Fauna Project | S13: Defenders of Wildlife | T13: Garrett College | U13: Unnamed expert in sustainable business | V13: Grand Traverse Regional Land Conservancy | W13: Three Rivers Parks District | X13: Louisiana Department of Wildlife and Fisheries | Y13: Mark Twain National Forest | Z13: The Nature Conservancy | AA13: Farmers Union | AB13: US Fish and Wildlife Service USFWS | AC13: Massachusetts Natural Heritage and Endangered Species Program | AD13: Monmouth County Park System | AE13: New Mexico Department of Game and Fish | AF13: Georgia College | AH13: Oklahoma Department of Environmental Quality | AI13: Confederated Tribes of the Umatilla Indian Reservation | AJ13: Clyde Peelings Reptiland | AK13: Coastal Resources Management Council | AL13: College of Charleston | AM13: National Park Service | AN13: K Gregg Consulting | AP13: Utah Division of Wildlife Resources | AQ13: Sain Michaels College | AR13: Natural Resources Conservation Service NRCS | AS13: Wildlife Diversity Advisory Council | AT13: National Audubon Society | AU13: Fort McCoy | AV13: Fremont County Weed and Pest
A14: Conservation Southeast | B14: National Park Service | C14: City of Peoria | D14: National Park Service | E14: Delta Conservancy | F14: Bureau of Land Management | G14: Connecticut Department of Economic and Community Development | I14: US Geological Survey USGS | J14: Clayton State University | K14: US National Oceanic and Atmospheric Administration NOAA | L14: Idaho State University | M14: Forest Preserve District of Dupage County | N14: Pheasants Forever | O14: Iowa Coop Unit | P14: Kansas Department of Wildlife and Parks | Q14: Kentucky Department of Fish and Wildlife Resources | R14: Louisiana State University | S14: Downeast Lakes Land Trust | T14: Interstate Commission on the Potomac River Basin | U14: Unnamed municipal public works managers | V14: Gratiot Conservation District | W14: University of Minnesota | X14: Lower Mississippi Valley Joint Venture | Y14: Missouri Association of Soil and Water Conservation Districts | Z14: The Wilderness Society | AA14: Fontenelle Nature Association | AB14: US Forest Service USFS | AC14: National Oceanic and Atmospheric Administration NOAA | AD14: Monmouth University | AE14: New Mexico Environment Department | AF14: Georgia Museum of Natural History | AH14: Oklahoma Department of Transportation | AI14: Confederated Tribes of Warm Springs | AJ14: College of Charleston | AK14: Consultant | AL14: Colorado State University | AM14: Natural Resources Conservation Service NRCS | AN14: Knoxville Zoological Gardens | AP14: Utah Farm Bureau Federation | AQ14: Terwilliger Consulting | AR14: North Atlantic Landscape Conservation Cooperative | AT14: Natural Resources Conservation Service NRCS | AU14: Gathering Waters | AV14: Invenergy LLC
A15: Coosa Riverkeeper | B15: Pacific Coast Joint Venture | C15: Creative Resource Strategies | D15: Northwest Arkansas Land Trust | E15: Eremico | F15: Bureau of Reclamation | G15: Connecticut Department of Energy and Environmental Protection | I15: ZooTampa | J15: Clemson University | L15: Latah Soil and Water Conservation District | M15: Forest Preserves of Winnebago County | N15: Purdue University | O15: Iowa Cooperative Fish and Wildlife Research Unit | P15: Kansas Forest Service | Q15: Kentucky Division of Water | R15: Louisiana Tech | S15: Downeast Salmon Federation | T15: Maryland Biodiversity Project | U15: Unnamed private engineering firms | V15: Herpetological Resource and Management | W15: US Army Corps of Engineers | X15: Mississippi Band of Choctaw Indians | Y15: Missouri Audubon | Z15: US Fish and Wildlife Service USFWS | AA15: Grassland Foundation | AB15: US Geological Survey USGS | AC15: Natural Resources Conservation Service NRCS | AD15: Morris County Park Commission | AE15: New Mexico Museum of Natural History and Science | AF15: Midwest Biodiversity Institute | AH15: Oklahoma Department of Wildlife Conservation | AI15: Consultant | AJ15: College of New Jersey | AK15: Environmental Protection Agency | AL15: Columbia University | AM15: Nebraska Game and Parks Commission | AN15: Lee University | AP15: Utah State University | AQ15: The Nature Conservancy | AR15: North Virginia Regional Commission | AT15: NatureServe | AU15: Great Lakes Indian Fish and Wildlife Commission | AV15: LS Power
A16: Nongame Conference Amphibian and Reptile Committee | B16: University of Alaska Fairbanks | C16: Federal Highway Administration | D16: Southern Arkansas University | E16: Foundations of Success | F16: City of Boulder Open Space and Mountain Parks | G16: Connecticut Department of Transportation | J16: Columbus State University | L16: National Park Service | M16: Heartlands Conservancy | N16: The Nature Conservancy | O16: Iowa Department of Natural Resources | P16: Kansas Forest Service, Kansas State University | Q16: Kentucky Herpetological Society | R16: Loyola University | S16: Ducks Unlimited | T16: Maryland Bird Conservation Initiative | U16: Unnamed regional planning agencies | V16: Huron River Watershed Council | W16: US Fish and Wildlife Service USFWS | X16: Mississippi Bat Working Group | Y16: Missouri Bird Conservation Initiative | Z16: US Forest Service USFS | AA16: Lincoln Public Schools | AB16: Walker River Paiute Tribe | AC16: New Boston Air Force Base | AD16: National Oceanic and Atmospheric Administration NOAA | AE16: New Mexico State Land Office | AF16: Nash Community College | AH16: Oklahoma Master Naturalists Program | AI16: Defenders of Wildlife | AJ16: Delaware River Basin Commission | AK16: Johnson and Wales University | AL16: Consultant | AM16: Northern Great Plains Joint Venture | AN16: Lincoln Memorial University | AP16: Utah Wildlife in Need | AQ16: University of Vermont | AR16: Northern Neck Planning District Commission | AT16: Northeast Partners in Amphibian and Reptile Conservation | AU16: Milwaukee County Zoo | AV16: National Park Service
A17: Nongame Conference Bird Committee | B17: US Fish and Wildlife Service USFWS | C17: Fort Huachuca | D17: The Arkansas Natural Heritage Commission | E17: National Park Service | F17: City of Fort Collins | G17: Connecticut Fisheries Advisory Council | J17: Conservation Fisheries | L17: Natural Resources Conservation Service NRCS | M17: Huff and Huff | N17: TrendyMinds | O17: Iowa Department of Transportation | P17: Kansas Grazing Lands Coalition | Q17: Kentucky Herpetological Society, Louisville Zoo | R17: McNeese State University | S17: Endangered Species Coalition | T17: Maryland Coastal Bays Program | U17: US Geological Survey USGS | V17: Huron-Clinton Metroparks | W17: Warner Nature Center | X17: Mississippi Chapter of The Wildlife Society | Y17: Missouri Botanical Garden | Z17: Wildlife Conservation Society | AA17: Missouri Department of Conservation | AB17: Xerces Society | AC17: New Hampshire Audubon | AD17: National Park Service | AE17: New Mexico State Parks | AF17: National Bobwhite Conservation Initiative | AH17: Oklahoma Native Plant Society | AI17: Greenbelt Land Trust | AJ17: Delaware Valley College | AK17: Land Management Services | AL17: Culture and Heritage Museums | AM17: Northern Prairies Land Trust | AN17: Middle Tennessee State University | AP17: Wild Utah Project | AQ17: US Fish and Wildlife Service USFWS | AR17: Richmond Regional Planning District Commission | AT17: Northeast State Fish and Wildlife Technical Committee | AU17: Milwaukee Public Museum | AV17: Natural Resources Conservation Service NRCS
A18: Nongame Conference Crayfish Committee | B18: US Geological Survey USGS | C18: Friends of Northern Arizona Forests | D18: The Nature Conservancy | E18: Point Blue Conservation Science | F18: City of Loveland | G18: Connecticut Forest and Park Association | J18: Consultant | L18: Nez Perce Soil and Water Conservation District | M18: Illinois Audubon Society | N18: US Fish and Wildlife Service USFWS | O18: Iowa Environmental Council | P18: Kansas Native Plant Society | Q18: Kentucky Native Plant Society | R18: Mississippi State University | S18: Forest Society of Maine | T18: Maryland Department of Natural Resources | V18: Jackson County Conservation District | X18: Mississippi Department of Environmental Quality | Y18: Missouri Caves and Karst Conservancy | AA18: National Park Service | AC18: New Hampshire Department of Environmental Services | AD18: Natural Resources Conservation Service NRCS | AE18: New Mexico State University | AF18: National Oceanic and Atmospheric Administration NOAA | AH18: Oklahoma Natural Heritage Inventory | AI18: Institute for Applied Ecology | AJ18: Dickinson College | AK18: Lloyd Center for Environmental Studies | AL18: Davidson College | AM18: Northern State University | AN18: Midwest Biodiversity Institute | AQ18: Vermont Agency of Transportation | AR18: South Atlantic Landscape Conservation Cooperative | AT18: Oglebay Institute | AU18: Minnesota Department of Natural Resources | AV18: Peabody Energy
A19: Nongame Conference Fishes Committee | C19: Grand Canyon University | D19: University of Arkansas | E19: San Francisco Bay Joint Venture | F19: Clear Creek Land Conservancy | G19: Connecticut Land Conservation Council | J19: Cumberland Island Museum | L19: Nez Perce Tribe | M19: Illinois Chapter of Sierra Club | N19: US Forest Service USFS | O19: Iowa Farm Bureau Federation | P19: Kansas Natural Resource Council | Q19: Kentucky Nature Preserves | R19: National Marine Fisheries Service | S19: GrowSmart Maine | T19: Maryland Department of the Environment | V19: John Ball Zoo | X19: Mississippi Department of Marine Resources | Y19: Missouri Community Forestry Council | AA19: Natural Resources Conservation Service NRCS | AC19: New Hampshire Department of Resources and Economic Development | AD19: New Jersey Audubon Society | AE19: Northern Arizona University | AF19: National Park Service | AH19: Oklahoma Ornithological Society | AI19: Institute for Natural Resources | AJ19: Drexel University | AK19: Mason and Associates | AL19: Edisto Island Serpentarium | AM19: Oglala Sioux Parks and Recreation Authority | AN19: Nashville Metropolitan Planning Organization | AQ19: Vermont Center for Ecostudies | AR19: Southeast Atlantic Slope Mollusk Group | AT19: Oglebay Zoo | AU19: Natural Resources Conservation Service NRCS | AV19: Petroleum Association of Wyoming
A20: Nongame Conference Mammal Committee | C20: Hopi Tribe | D20: University of Arkansas-Little Rock | E20: Sitka Technology | F20: Colorado Beekeepers | G20: Connecticut National Guard Armory | J20: Dalton State College | L20: Northwest Nazarene University | M20: Illinois Chapter of the American Fisheries Society | O20: Iowa Farmers Union | P20: Kansas Ornithological Society | Q20: Kentucky Ornithological Society | R20: National Oceanic and Atmospheric Administration NOAA | S20: Gulf of Maine Research Institute | T20: Maryland Entomological Society | V20: Kalamazoo Nature Center | X20: Mississippi Department of Wildlife, Fisheries and Parks | Y20: Missouri Conservation Heritage Foundation | AA20: Nebraska Alliance for Conservation and Environment Education | AC20: New Hampshire Fish and Game | AD20: New Jersey Conservation Foundation | AE20: Prescott College | AF20: Natural Resources Conservation Service NRCS | AH20: Oklahoma Scenic Rivers Commission | AI20: Intertwine Alliance | AJ20: Duquesne University | AK20: Napatree Conservancy | AL20: Erskine College | AM20: Oglala Sioux Tribe | AN20: Nashville Zoo | AQ20: Vermont Department of Environmental Conservation | AR20: The Nature Conservancy | AT20: Ohio River Islands National Wildlife Refuge | AU20: Northland College | AV20: Rio Tinto Energy of America
A21: Nongame Conference Mussels and Snails Committee | C21: Maricopa County | D21: University of Arkansas-Monticello | E21: The Nature Conservancy | F21: Colorado Cattlemen's Agricultural Land Trust | G21: Connecticut Office of Policy and Management | J21: Dinkins Biological Consulting | L21: Owyhee County | M21: Illinois Department of Agriculture | O21: Iowa Natural Heritage Foundation | P21: Kansas State University | Q21: Kentucky Reptile Zoo | R21: National Park Service | S21: Houlton Band of Maliseet Indians | T21: Maryland Herpetological Society | V21: Kirtlands Warbler Alliance | X21: Mississippi Development Authority | Y21: Missouri Department of Agriculture | AA21: Nebraska Association of Resources Districts | AC21: New Hampshire Natural Heritage | AD21: New Jersey Department of Environmental Protection | AE21: Sierra Club | AF21: North Carolina Department of Agriculture and Consumer Services | AH21: Oklahoma State University | AI21: Klamath Bird Observatory | AJ21: East Stroudsburg University | AK21: Narragansett Bay Estuary Program | AL21: Francis Marion University | AM21: Prairie Pothole Joint Venture | AN21: National Park Service | AQ21: Vermont Fish and Wildlife Department | AR21: US Department of Defense DOD | AT21: The Conservation Fund's Freshwater Institute | AU21: Ozaukee County | AV21: Rocky Mountain Elk Foundation
A22: North River Watershed, University of Alabama | C22: Matrix Design Group | D22: University of Central Arkansas | E22: Trout Unlimited | F22: Colorado Coalition of Land Trusts | G22: Connecticut Ornithological Association | J22: Ecological Solutions | L22: Potlatch Forest Holdings, Inc. | M22: Illinois Department of Natural Resources | O22: Iowa Natural Resources Commission | P22: Kansas Walleye Association | Q22: Kentucky State University | R22: Nicholls State University | S22: Island Institute | T22: Maryland Ornithological Society | V22: Little Traverse Bay Bands of Odawa Indians | X22: Mississippi Forestry Commission | Y22: Missouri Department of Conservation | AA22: Nebraska Audubon | AC22: Northeast Climate Science Center | AD22: New Jersey Department of Transportation | AE22: Texas Tech University | AF22: North Carolina Department of Environment and Natural Resources | AH22: Olsson Environmental | AI22: League of Oregon Cities | AJ22: Eastern Pennsylvania Coalition of Abandonded Mine Reclamation | AK22: Narragansett Bay National Estuarine Research Reserve | AL22: Furman University | AM22: Rosebud Sioux Tribe | AN22: National Wildlife Federation | AQ22: Vermont Forest Parks and Recreation Department | AR22: US Fish and Wildlife Service USFWS | AT22: The Nature Conservancy | AU22: Red Cliff Band of Lake Superior Chippewas | AV22: Rocky Mountain Power
A23: Poarch Creek Tribe | C23: McDowell Sonoran Preserve | D23: US Army Corps of Engineers | E23: UC Berkeley | F23: Colorado College | G23: Connecticut Professional Timber Producers | J23: Eco-Tech Consultants | L23: POWER Engineers, Inc | M23: Illinois Department of Transportation | O23: Iowa NatureMapping | P23: Kansas Wildlife Federation | Q23: Mammoth Cave National Park | R23: Northwestern State University of Louisiana | S23: Lakes Environmental Association | T23: Mid-Atlantic Invertebrate Field Studies | V23: MIARNG | X23: Mississippi Sandhill Crane National Wildlife Refuge | Y23: Missouri Department of Natural Resources | AA23: Nebraska Bird Partnership | AC23: Shoals Marine Lab | AD23: New Jersey Endangered and Nongame Species Advisory Committee | AE23: Turner Biological | AF23: North Carolina Department of Parks and Recreation | AH23: Ouachita National Forest | AI23: Lewis and Clark College | AJ23: French and Pickering Creeks Conservation Trust | AK23: Narragansett Bay Research Reserve | AL23: Georgia Department of Natural Resources GADNR | AM23: Sisseton-Wahpeton Oyate | AN23: Natural Resources Conservation Service NRCS | AQ23: Vermont Herp Atlas | AR23: US Forest Service USFS | AT23: The World Conservation Union | AU23: Rivers Alliance | AV23: Ruckelshaus Institute of Environment and Natural Resources
A24: Tennessee Valley Authority | C24: National Park Service | D24: US Fish and Wildlife Service USFWS | E24: UC Davis | F24: Colorado Counties Inc. | G24: Connecticut River Gateway Commission | J24: Edwards-Pitman | L24: Shoshone-Bannock Tribes | M24: Illinois Endangered Species Protection Board | O24: Iowa Odonata Society | P24: Konza Prairie Biological Station | Q24: Morehead State University | R24: Southeastern Bat Conservation Network | S24: Main Discovery Museum | T24: National Aquarium in Baltimore | V24: Michigan Association of Conservation Districts | X24: Mississippi Soil and Water Conservation Commission | Y24: Missouri Department of Transportation | AA24: Nebraska Cattlemen | AC24: Society for the Protection of New Hampshire Forests | AD24: New Jersey Fish and Game Council | AE24: University of Arizona | AF24: North Carolina Department of Transportation | AH24: Peoria Nation | AI24: National Oceanic and Atmospheric Administration NOAA | AJ24: Gettysburg College | AK24: Narragansett Chapter of Trout Unlimited | AL24: Greenville Zoo | AM24: South Dakota Department of Agriculture | AN24: Open Space Institute | AQ24: Vermont Land Trust | AR24: Virginia Audubon Society | AT24: Thomas Jefferson National Forest | AU24: Shedd Aquarium | AV24: Sheridan County
A25: Terwilliger Consulting | C25: Navajo Nation Department of Fish and Wildlife | D25: US Forest Service USFS | E25: UC Riverside | F25: Colorado Department of Agriculture | G25: Connecticut River Salmon Association | J25: Enduring Conservation Outcomes | L25: Sitka Technology Group | M25: Illinois Environmental Protection Agency | O25: Iowa Ornithologist Union | P25: Mid-American All-Indian Center | Q25: Murray State University | R25: Southeastern Louisiana University | S25: Maine Aquaculture Association | T25: National Oceanic and Atmospheric Administration NOAA | V25: Michigan Audubon | X25: Mississippi State University | Y25: Missouri Farm Bureau | AA25: Nebraska Corn Board | AC25: St Anselm College | AD25: New Jersey Pinelands Commission | AE25: University of New Mexico | AF25: North Carolina Division of Parks and Recreation | AH25: Rogers State University | AI25: Natural Resources Conservation Service NRCS | AJ25: Hawk Mountain Sanctuary | AK25: Narragansett Indian Tribe | AL25: Indiana University | AM25: South Dakota Department of Environment and Natural Resources | AN25: Shortleaf Pine Initiative | AQ25: Vermont Natural Resources Council | AR25: Virginia Department of Conservation and Recreation | AT25: University of Alabama | AU25: Snapping Linton Ecology | AV25: Sonoran Institute
A26: The Longleaf Alliance | C26: Northern Arizona University | D26: US Geological Survey USGS | E26: US Fish and Wildlife Service USFWS | F26: Colorado Department of Natural Resources | G26: Connecticut River Watershed Association | J26: Flint Riverquarium | L26: Stimson Lumber Company | M26: Illinois Farm Bureau | O26: Iowa Pork Producers Association | P26: National Wild Turkey Federation | Q26: Northern Kentucky University | R26: Texas State University | S26: Maine Army National Guard | T26: Natural History Society of Maryland | V26: Michigan Department of Environmental Quality | X26: Mississippi Wildlife Federation | Y26: Missouri Forest Products Association | AA26: Nebraska Department of Agriculture | AC26: St Paul's School, Northeast Ecological Services | AD26: New Jersey Shellfish Council | AE26: US Army Corps of Engineers | AF26: North Carolina Division of Water Quality | AH26: Sam Noble Oklahoma Museum of Natural History | AI26: Network of Oregon Watershed Councils | AJ26: Indiana University of Pennsylvania | AK26: National Oceanic and Atmospheric Administration NOAA | AL26: Iowa State University | AM26: South Dakota Department of Transportation | AN26: Southeast Aquatic Resources Partnership | AR26: Virginia Department of Environmental Quality | AT26: US Fish and Wildlife Service USFWS | AU26: Southeastern Wisconsin Regional Planning Commission | AV26: The Nature Conservancy
A27: The Nature Conservancy | C27: Phoenix Zoo | E27: US Forest Service USFS | F27: Colorado Department of Transportation | G27: Connecticut Shellfish and Aquaculture Program | J27: Florida Fish and Wildlife Conservation Commission | L27: Teton Regional Land Trust | M27: Illinois Federation for Outdoor Resources | O27: Iowa Prairie Network | P27: Natural Resources Conservation Service NRCS | Q27: Society of Kentucky Lepidopterists | R27: Texas Tech University | S27: Maine Association of Conservation Commissions | T27: Patuxent River Naval Air Station | V27: Michigan Department of Natural Resources | X27: National Park Service | Y27: Missouri Landscape and Nursery Association | AA27: Nebraska Department of Education | AC27: The Nature Conservancy | AD27: New Jersey State Forestry Service | AE27: US Bureau of Land Management | AF27: North Carolina Division of Water Resources | AH27: Smith Environmental Research and Consulting | AI27: Oregon Association of Conservation Districts | AJ27: Interactive Environmental Programs | AK27: National Park Service | AL27: Kentucky Department of Natural Resources | AM27: South Dakota Department of Tribal Relations | AN27: Southeast Missouri State University | AR27: Virginia Department of Forestry | AT27: US Forest Service USFS | AU27: Southern Connecticut State University | AV27: Trout Unlimited
A28: Trutta Consulting | C28: Pima County | E28: US Navy | F28: Colorado Field Ornithologists | G28: Connecticut Soil and Water Conservation Districts | J28: Florida Natural Areas Inventory | L28: The Nature Conservancy | M28: Illinois Forestry Development Council | O28: Iowa Rehabilitators Association | P28: Pheasants Forever and Quail Forever | Q28: Stantec | R28: The Nature Conservancy | S28: Maine Association of Planners | T28: Randolph-Macon College | V28: Michigan Department of Transportation | X28: National Wild Turkey Federation | Y28: Missouri Native Plant Society | AA28: Nebraska Environmental Trust | AC28: University of Massachusetts | AD28: Oysters Crabs and Soft Crabs | AE28: US Bureau of Reclamation | AF28: North Carolina Forest Service | AH28: Southeastern Oklahoma State University | AI28: Oregon Biodiversity Information Center | AJ28: Juniata Valley Audubon | AK28: National Wildlife Federation | AL28: Lander College | AM28: South Dakota Game, Fish and Parks | AN28: Southern Environmental Law Center | AR28: Virginia Department of Game and Inland Fisheries | AT28: Virginia Department of Game and Inland Fisheries | AU28: St Marys University | AV28: University of Wyoming
A29: University of Alabama (student) | C29: Pinal County | F29: Colorado Hawking Club | G29: Connecticut Waterfowlers Association | J29: Fort Gordon Army Base | L29: Trout Unlimited | M29: Illinois Green Industry Association | O29: Iowa State University | P29: Pittsburg State University | Q29: The Nature Conservancy | R29: Thibodaux Live Supply | S29: Maine Association of Wetland Scientists | T29: Salisbury University | V29: Michigan Environmental Council | X29: National Wildlife Federation | Y29: Missouri Park and Recreation Association | AA29: Nebraska Farm Bureau | AC29: University of New Hampshire | AD29: Pinelands Preservation Alliance | AE29: US Fish and Wildlife Service USFWS | AF29: North Carolina Museum of Natural History | AH29: Southwestern Oklahoma State University | AI29: Oregon Cattlemens Association | AJ29: Lehigh University | AK29: Natural Resources Conservation Service NRCS | AL29: Macon State College | AM29: South Dakota Governors Office | AN29: Tennessee Aquarium | AR29: Virginia Institute of Marine Science | AT29: West Liberty University | AU29: Stantec | AV29: UR Energy
A30: US Army Corps of Engineers | C30: Quail Forever Phesants Forever | F30: Colorado Headwaters Land Trust | G30: Ducks Unlimited | J30: Georgia 4H | L30: Trumpeter Swan Society | M30: Illinois Nature Preserves Commission | O30: Iowa Trappers Association | P30: Playa Lakes Joint Venture | Q30: Touchstone Energy | R30: Towson University | S30: Maine Audubon Society | T30: Sierra Club | V30: Michigan Natural Features Inventory | X30: National Wildlife Refuge | Y30: Missouri Parks Association | AA30: Nebraska Forest Service | AC30: University of Vermont | AD30: PSEG Services Corporation | AE30: US Forest Service USFS | AF30: North Carolina Museum of Natural Sciences | AH30: Sutton Avian Research Center | AI30: Oregon Chapter of American Fisheries Society | AJ30: Lock Haven University | AK30: New England Fishery Management Council | AL30: Nash Community College | AM30: South Dakota Office of School and Public Lands | AN30: Tennessee Clean Water Network | AR30: Virginia Marine Resources Commission | AT30: West Virginia Conservation Agency | AU30: Stockbridge-Munsee Community | AV30: US Department of Agriculture
A31: US Fish and Wildlife Service USFWS | C31: Research Foundation for The State University of New York Environmental Science and Forestry SUNY | F31: Colorado Mountain Club | G31: Farmington River Watershed Association | J31: Georgia Aquarium | L31: University of Idaho | M31: Illinois Pollution Control Board | O31: Iowa Tree Farm Committee | P31: Sierra Club | Q31: University of Kentucky | R31: Tulane University | S31: Maine Birding Trail | T31: Smithsonian | V31: Michigan Nature Association | X31: Natural Resource Enterprises | Y31: Missouri Prairie Foundation | AA31: Nebraska Game and Parks Commission | AC31: US Fish and Wildlife Service USFWS | AD31: Rowan University | AE31: Western New Mexico University | AF31: North Carolina Natural Heritage Program | AH31: The Nature Conservancy | AI31: Oregon Chapter of The Wildlife Society | AJ31: Messiah College | AK31: New England Interstate Water Pollution Control Commission | AL31: National Oceanic and Atmospheric Administration NOAA | AM31: South Dakota State University | AN31: Tennessee Department of Environment and Conservation | AR31: Virginia Society of Ornithology | AT31: West Virginia Cooperative Fish and Wildlife Research Unit | AU31: The Nature Conservancy | AV31: US Fish and Wildlife Service USFWS
A32: US Forest Service USFS | C32: Salt River Pima Maricopa Indian Community | F32: Colorado Native Plant Society | G32: Federal Aviation Administration FAA | J32: Georgia Botanical Society | L32: US Army Corps of Engineers | M32: Jo Daviess Conservation Foundation | O32: Iowa Wildlife Center | P32: Stantec | Q32: US Fish and Wildlife Service USFWS | R32: University New Orleans | S32: Maine Bowhunters Association | T32: Susquehannock Wildlife Society | V32: Michigan State University | X32: Natural Resources Conservation Service NRCS | Y32: Missouri Resource Assessment Partnership | AA32: Nebraska Land Trust | AC32: US Forest Service USFS | AD32: Rutgers University | AE32: White Sands Missile Range | AF32: North Carolina State University | AH32: The Samuel Roberts Noble Foundation | AI32: Oregon Department of Agriculture | AJ32: Mid-Atlantic Center for Herpetology and Conservation | AK32: New England Plant Conservation Program | AL32: North American Native Fishes Association | AM32: Standing Rock Sioux Tribe | AN32: Tennessee Ornithological Society | AR32: Virginia Tech | AT32: West Virginia Council Trout Unlimited | AU32: The Prairie Enthusiasts | AV32: US Forest Service USFS
A33: US Geological Survey USGS | C33: Sierra Club Arizona | F33: Colorado Natural Areas Program | G33: Green Valley Institute (UConn and UMass partnership) | J33: Georgia College and State University | L33: US Bureau of Land Management | M33: Jo Daviess County Soil and Water Conservation District | O33: Iowa Woodland Owners Association | P33: Sternberg Museum of Natural History | Q33: US Forest Service USFS | R33: University of Louisiana | S33: Maine Chamber of Commerce | T33: The Nature Conservancy | V33: Michigan Technological University | X33: Office of Senator Thad Cochran | Y33: Missouri Stream Team Watershed Coalition | AA33: Nebraska Ornithologists Union | AC33: Vermont Center for Ecostudies | AD33: South Jersey Resource Conservation and Development | AF33: North Carolina Wildlife Federation | AH33: Tinker Air Force Base | AI33: Oregon Department of Energy | AJ33: Millersville University | AK33: Pheasants Forever | AL33: North Carolina Division of Marine Fisheries | AM33: University of South Dakota | AN33: Tennessee Parks and Greenways Foundation | AR33: Xerces Society | AT33: West Virginia Department of Environmental Protection | AU33: TRC Environmental | AV33: Water Management Coordinator
C34: The Nature Conservancy | F34: Colorado Natural Heritage Program | G34: Hartford Armory | J34: Georgia Conservancy | L34: US Bureau of Reclamation | M34: Lake County Forest Preserve District | O34: Linn County Conservation Board | P34: The Nature Conservancy | Q34: Western Kentucky University | R34: University of New Orleans | S34: Maine Chapter of the Sierra Club | T34: Towson University | V34: Michigan United Conservation Clubs | X34: Partnership for Gulf Coast Land Conservation | Y34: Missouri Tree Farm Committee | AA34: Nebraska Prairie Partners | AC34: Wells National Estuarine Research Reserve | AD34: Stockton University | AF34: North Carolina Wildlife Resources Commission | AH34: University of Central Oklahoma | AI34: Oregon Department of Environmental Quality | AJ34: Moravian College | AK34: Providence Water | AL34: North Carolina Museum of Natural History | AM34: US Army Corps of Engineers | AN34: Tennessee Technological University | AT34: West Virginia Department of Natural Resources | AU34: Trout Unlimited | AV34: Wildlife Conservation Society
C35: Tuscon Audubon Society | F35: Colorado Openlands | G35: Hartford Sportsmen Club | J35: Georgia Department of Education | L35: US Department of Agriculture | M35: Lincoln Park Zoo | O35: Loess Hills Alliance | P35: US Army Corps of Engineers | R35: US Department of Agriculture | S35: Maine Chapter of the Wildlife Society | T35: University of Delaware | V35: National Audubon Society | X35: Pascagoula River Audubon Center | Y35: National Park Service | AA35: Nebraska Wildlife Federation | AD35: Supawna Meadows National Wildlife Refuge | AF35: Ohio Department of Natural Resources | AH35: University of Oklahoma | AI35: Oregon Department of Fish and Wildlife | AJ35: National Aviary | AK35: Rhode Island Association of Wetland Scientists | AL35: North Carolina Museum of Natural Sciences | AM35: US Fish and Wildlife Service USFWS | AN35: Tennessee Valley Authority | AT35: West Virginia Division of Forestry | AU35: University of Connecticut | AV35: Wildlife Heritage Foundation of Wyoming
C36: University of Arizona | F36: Colorado Outfitters Association | G36: Maritime Aquarium at Norwalk | J36: Georgia Department of Natural Resources GADNR | L36: US Department of Energy | M36: Little River Research and Design | O36: Loess Hills Audubon | P36: US Department of Agriculture | R36: US Fish and Wildlife Service USFWS | S36: Maine Coast Heritage Trust | T36: University of Maryland | V36: National Wild Turkey Federation | X36: Southern Company | Y36: National Wild Turkey Federation | AA36: Nebraska Wildlife Society | AD36: The Nature Conservancy | AF36: Piedmont Land Conservancy | AH36: University of Science and Arts of Oklahoma | AI36: Oregon Department of Forestry | AJ36: National Park Service | AK36: Rhode Island College | AL36: North Carolina State University | AM36: US Forest Service USFS | AN36: Tennessee Wildlife Federation | AT36: West Virginia Division of Highways | AU36: University of Minnesota | AV36: Wyoming Bureau of Land Management
C37: US Air Force Luke Air Force Base | F37: Colorado Pesticide Network | G37: Mashantucket Pequot Tribal Nation | J37: Georgia Department of Transportation | L37: US Fish and Wildlife Service USFWS | M37: Living Lands and Waters | O37: MacBride Raptor Center | P37: US Fish and Wildlife Service USFWS | R37: US Forest Service USFS | S37: Maine Coastal Program | T37: US Department of Agriculture | V37: National Wildlife Federation | X37: The Nature Conservancy | Y37: Natural Resources Conservation Service NRCS | AA37: Northern Prairies Land Trust | AD37: The Wetlands Institute | AF37: Smith College | AH37: University of Tulsa | AI37: Oregon Department of Land Conservation and Development | AJ37: Natural History Museum, Tom Ridge Environmental Center | AK37: Rhode Island Department of Environmental Management | AL37: North Carolina Wildlife Resources Commission | AM37: US Geological Survey USGS | AN37: Tennessee Wildlife Resources Agency | AT37: West Virginia Entomological Society | AU37: University of Wisconsin | AV37: Wyoming Department of Agriculture
C38: US Army Yuma Proving Ground | F38: Colorado Sportsmen's Roundtable | G38: Mid-Atlantic Fishery Management Council | J38: Georgia Environmental Finance Authority | L38: US Forest Service USFS | M38: Loyola University | O38: Morningside College | P38: Westar Energy Company | R38: US Geological Survey USGS | S38: Maine Cooperative Fish and Wildlife Research Unit | T38: US Department of Energy | V38: Organization for Bat Conservation | X38: The Trust for Public Land | Y38: Ozark Regional Land Trust | AA38: Omaha Henry Doorly Zoo | AD38: Unaffiliated private consultants | AF38: Tennessee Valley Authority | AH38: US Fish and Wildlife Service USFWS | AI38: Oregon Department of State Lands | AJ38: Natural Resources Conservation Service NRCS | AK38: Rhode Island Ducks Unlimited | AL38: Piedmont College | AM38: Wind Cave National Park | AN38: The Land Trust for Tennessee | AT38: West Virginia Land Trust | AU38: US Department of Agriculture | AV38: Wyoming Game and Fish Department
C39: US Bureau of Reclamation | F39: Colorado Springs Utilities | G39: Mohegan Tribal Nation | J39: Georgia Forestry Association | L39: US Geological Survey USGS | M39: Max McGraw Wildlife Foundation | O39: National Park Service | P39: Wichita Audubon Society | S39: Maine Department of Agriculture, Conservation and Forestry | T39: US Fish and Wildlife Service USFWS | V39: Pheasants Forever | X39: University of Mississippi | Y39: Pheasants Forever | AA39: Pheasants Forever | AD39: US Department of Defense DOD | AF39: Texas A&M University | AI39: Oregon Department of Transportation | AJ39: NatureServe | AK39: Rhode Island Forest Conservators Organization | AL39: Purdue University | AN39: The Nature Conservancy | AT39: West Virginia Master Naturalist Program | AU39: US Fish and Wildlife Service USFWS | AV39: Wyoming Governors Office
C40: US Department of Agriculture USDA Wildlife Services | F40: Colorado State Forest Service | G40: Mystic Aquarium | J40: Georgia Forestry Commission | M40: McHenry County Conservation District | O40: National Wild Turkey Federation | S40: Maine Department of Environmental Protection | T40: US Geological Survey USGS | V40: Pierce Cedar Creek Institute | X40: University of Southern Mississippi | Y40: Prairies Forever | AA40: Ponca Tribe of Nebraska | AD40: US Fish and Wildlife Service USFWS | AF40: The Catena Group | AI40: Oregon Farm Bureau | AJ40: North Carolina Museum of Natural Sciences | AK40: Rhode Island Geographic Information System | AL40: Randolf Rattlesnake Refuge and Research Center | AN40: Trout Unlimited | AT40: West Virginia Outdoor Heritage Conservation Fund | AU40: US Forest Service USFS | AV40: Wyoming Land Trust
...

Sheet SGCN Species
A1: State | B1: SGCN (2015) | C1: Total Number of Agencies
A2: Alabama | B2: 366 | C2: =Alabama!G37 -> 26
A3: Alaska | B3: 376 | C3: =Alaska!G25 -> 17
A4: Arizona | B4: 551 | C4: =Arizona!G55 -> 46
A5: Arkansas | B5: 377 | C5: =Arkansas!G30 -> 25
A6: California | B6: 1157 | C6: =California!G32 -> 27
A7: Colorado* | B7: 351 | C7: =Colorado!G159 -> 154
A8: Connecticut* | B8: 566 | C8: =Connecticut!G77 -> 72
A9: Delaware | B9: 692 | C9: =Delaware!G17 -> 12
A10: Florida | B10: 690 | C10: =Florida!G20 -> 14
A11: Georgia | B11: 640 | C11: =Georgia!G103 -> 98
A12: Hawaii | B12: 1323 | C12: =Hawaii!G23 -> 13
A13: Idaho | B13: 205 | C13: =Idaho!G43 -> 38
A14: Illinois | B14: 421 | C14: =Illinois!G74 -> 69
A15: Indiana | B15: 593 | C15: =Indiana!G23 -> 18
A16: Iowa | B16: 405 | C16: =Iowa!G61 -> 55
A17: Kansas | B17: 285 | C17: =Kansas!G43 -> 38
A18: Kentucky | B18: 301 | C18: =Kentucky!G39 -> 33
A19: Louisiana | B19: 694 | C19: =Louisiana!G43 -> 37
A20: Maine | B20: 378 | C20: =Maine!G92 -> 82
A21: Maryland | B21: 610 | C21: =Maryland!G49 -> 40
A22: Massachusetts | B22: 570 | C22: =Massachusetts!G25 -> 11
